<mujoco model="planar_snake_prototype">
    <compiler angle="degree" coordinate="local" inertiafromgeom="true"/>

    <option integrator="Euler" timestep="0.0125">
        <flag energy="enable" clampctrl="enable"/>
    </option>

    <size nconmax="1000" njmax="8000"/>

    <default>

<!--         <geom conaffinity="0" condim="3" friction="1.0 0.005 0.0001" margin="0.0001" density="1144" />
        <joint armature='0.01' damping="0.4" frictionloss="1.2" />
        <default class="wheel">
            <joint axis="0 1 0" type="hinge" damping="0.0001" armature='0.00001' frictionloss="0.0001"/>
            <geom solref="0.02 1" solimp="0.9 0.95 0.0001 " type="cylinder" fromto="0 0 0  0 0.006 0" size="0.009"
                  material="geom" rgba=".9 .9 .9 1" friction="1.2 0.005 0.001" density="1441" />
        </default> -->

        <geom conaffinity="0" condim="3" friction="1.0 0.005 0.0001" margin="0.0001" density="1144" />
        <joint armature='0.001' damping="0.32" frictionloss="1.3" />
        <default class="wheel">
            <joint axis="0 1 0" type="hinge" damping="0.00012" armature='0.00001' frictionloss="0.0032"/>
            <geom solref="0.03 1" solimp="0.9 0.95 0.0001 " type="cylinder" fromto="0 0 0  0 0.006 0" size="0.009" material="geom" rgba=".9 .9 .9 1" friction="3 0.005 0.001" density="1441" />
        </default>

        <default class="car">
            <!-- <geom type="mesh" mesh="module_asm_0107" fitscale="1"/> -->
            <!-- <geom material="geom" rgba="0.8 0.7 .6 1" /> -->
            <joint pos="0 0 0" axis="0 0 1" type="hinge" limited="true" range="-90 90"/>
        </default>

        <position ctrllimited="true" ctrlrange="-1.5 1.5" forcelimited="true" forcerange="-4 4" kp="10" gear="1"/>
    </default>

    <asset>
        <texture builtin="gradient" height="100" rgb1="1 1 1" rgb2="0 0 0" type="skybox" width="100"/>
        <texture builtin="flat" height="1278" mark="cross" markrgb="1 1 1" name="texgeom" random="0.01"
                 rgb1="0.8 0.6 0.4" rgb2="0.8 0.6 0.4" type="cube" width="127"/>
        <texture builtin="checker" height="100" name="texplane" rgb1=".2 .3 .4" rgb2=".1 0.15 0.2"  type="2d" width="100" gridsize="1 1"/>
        <material name="MatPlane" reflectance="0.5" shininess="1" specular="1" texrepeat="80 80" texture="texplane"/>
        <material name="geom" texture="texgeom" texuniform="true"/>
        <material name="MatTarget" rgba="1 0 0 1" reflectance="0.05" shininess="0.1" specular="0.1"/>
        <mesh file="/home/bing/Documents/git_bing/planar_snake_prototype_RL/planar_snake_prototype_RL/envs/assets/module_asm_0107.stl"
              scale="0.001 0.001 0.001"/>
        <material name="matplane" reflectance="0.3" texture="texplane" texrepeat="1 1" texuniform="true"/>
    </asset>


    <visual>
        <map znear="0.0625"  />
        <quality shadowsize="4096"/>

    </visual>


    <worldbody>
        <light cutoff="100" diffuse="1 1 1" dir="-0 0 -1.3" directional="true" exponent="1" pos="0 0 1.3"
               specular=".1 .1 .1"/>
        <geom name="floor" size="20 20 10" material="matplane" conaffinity="1" condim="3" pos="0 0 -0" rgba="0.8 0.9 0.8 1"
              type="plane" friction="1.0 0.005 0.0001"/>

        <!-- the first object is a target ball -->
        <body name="target_ball" pos="0.1 0 0.0">
            <joint axis="1 0 0" name="target_slider_x" type="slide"/>
            <joint axis="0 1 0" name="target_slider_y" type="slide"/>
            <geom name="target_ball_geom" type="sphere" pos="0.1 0 0.5" size="0.1" material="MatTarget"/>
            <camera name="track_ball" mode="trackcom" pos="0 -4 6" euler="30 0 0"/>
            <camera name="track_ball2" mode="targetbodycom" pos="0 0 1" zaxis="0 0 90" />
        </body>

        <!-- the second object is the robot -->
        <body name="car1" pos="0.024 -0.033 0.063">

            <joint axis="1 0 0" name="slider_x" type="slide"/>
            <joint axis="0 1 0" name="slider_y" type="slide"/>
            <joint axis="0 0 1" name="slider_z" type="slide"/>

            <joint pos="0 0 0" axis="1 0 0" name="hinge_x" type="hinge"/>
            <joint pos="0 0 0" axis="0 1 0" name="hinge_y" type="hinge"/>
            <joint pos="0 0 0" axis="0 0 1" name="hinge_z" type="hinge"/>

            <body pos="-0.051 0.0575 -0.054" childclass="wheel"><joint name="joint_wheel_l_00"/><geom/></body>

            <geom name="head" pos="0 0 0" type="mesh" mesh="module_asm_0107" material="geom" euler="270 270 0" rgba="0.8 0.7 .6 1"/>

            <body pos="-0.051 0.0025 -0.054" childclass="wheel"><joint name="joint_wheel_r_00"/><geom/></body>

            <site name='site_head' pos='-0.05 0.015 -0.015' type='box'  size='.01 .01 .01'/>
            <camera name="head" mode="fixed" pos="0 0 0.025" fovy="90" euler="90 -90 0"/>
            <camera name="track_snake1" mode="trackcom" pos="-1.4 -1.25 2.25" euler="30 0 0"/>
            <camera name="track_snake2" mode="trackcom" pos="-1.5 0 3" euler="0 0 0"/>
            <camera name="track_snake3" mode="trackcom" pos="0 -4 6" euler="30 0 0"/>
            <camera name="track_snake31" mode="trackcom" pos="1.25 -3.75 4.5" euler="30 0 0"/>
            <camera name="track_snake32" mode="trackcom" pos="-4.0 0.0 0.75" euler="00 -90 00"/>
            <camera name="track_snake33" mode="trackcom" pos="-4.5 0.0 1.75" xyaxes="0.0 -1 0.0 0.6 0 1 "/>
            <camera name="track_snake4" mode="trackcom" pos="0 0 5" euler="0 0 0"/>

                <body name="car2" pos="-0.08075 0 0.0" childclass="car">
                    <joint name="joint01" pos="-0.024 0.033 -0.030"/>
                    <body pos="-0.051 0.0575 -0.054" childclass="wheel"><joint name="joint_wheel_l_01"/><geom/></body>
                    <geom name="car2_geom" pos="0.0 0.0 0.0" type="mesh" mesh="module_asm_0107" material="geom" euler="270 270 0" rgba="0.8 0.7 .6 1"/>
                    <body pos="-0.051 0.0025 -0.054" childclass="wheel"><joint name="joint_wheel_r_01"/><geom/></body>

                    <body name="car3" pos="-0.08075 0 0.0" childclass="car">
                        <joint name="joint02" pos="-0.024 0.033 -0.030"/>
                        <body pos="-0.051 0.0575 -0.054" childclass="wheel"><joint name="joint_wheel_l_02"/><geom/></body>
                        <geom name="car3_geom" pos="0.0 0.0 0.0" type="mesh" mesh="module_asm_0107" material="geom" euler="270 270 0" rgba="0.8 0.7 .6 1"/>
                        <body pos="-0.051 0.0025 -0.054" childclass="wheel"><joint name="joint_wheel_r_02"/><geom/></body>

                        <body name="car4" pos="-0.08075 0 0.0" childclass="car">
                            <joint name="joint03" pos="-0.024 0.033 -0.030"/>
                            <body pos="-0.051 0.0575 -0.054" childclass="wheel"><joint name="joint_wheel_l_03"/><geom/></body>
                            <geom name="car4_geom" pos="0.0 0.0 0.0" type="mesh" mesh="module_asm_0107" material="geom" euler="270 270 0" rgba="0.8 0.7 .6 1"/>
                            <body pos="-0.051 0.0025 -0.054" childclass="wheel"><joint name="joint_wheel_r_03"/><geom/></body>

                            <body name="car5" pos="-0.08075 0 0.0" childclass="car">
                                <joint name="joint04" pos="-0.024 0.033 -0.030"/>
                                <body pos="-0.051 0.0575 -0.054" childclass="wheel"><joint name="joint_wheel_l_04"/><geom/></body>
                                <geom name="car5_geom" pos="0.0 0.0 0.0" type="mesh" mesh="module_asm_0107" material="geom" euler="270 270 0" rgba="0.8 0.7 .6 1"/>
                                <body pos="-0.051 0.0025 -0.054" childclass="wheel"><joint name="joint_wheel_r_04"/><geom/></body>

                                <body name="car6" pos="-0.08075 0 0.0" childclass="car">
                                    <joint name="joint05" pos="-0.024 0.033 -0.030"/>
                                    <body pos="-0.051 0.0575 -0.054" childclass="wheel"><joint name="joint_wheel_l_05"/><geom/></body>
                                    <geom name="car6_geom" pos="0.0 0.0 0.0" type="mesh" mesh="module_asm_0107" material="geom" euler="270 270 0" rgba="0.8 0.7 .6 1"/>
                                    <body pos="-0.051 0.0025 -0.054" childclass="wheel"><joint name="joint_wheel_r_05"/><geom/></body>

                                    <body name="car7" pos="-0.08075 0 0.0" childclass="car">
                                        <joint name="joint06" pos="-0.024 0.033 -0.030"/>
                                        <body pos="-0.051 0.0575 -0.054" childclass="wheel"><joint name="joint_wheel_l_06"/><geom/></body>
                                        <geom name="car7_geom" pos="0.0 0.0 0.0" type="mesh" mesh="module_asm_0107" material="geom" euler="270 270 0" rgba="0.8 0.7 .6 1"/>
                                        <body pos="-0.051 0.0025 -0.054" childclass="wheel"><joint name="joint_wheel_r_06"/><geom/></body>

                                        <body name="car8" pos="-0.08075 0 0.0" childclass="car">
                                            <joint name="joint07" pos="-0.024 0.033 -0.030"/>
                                            <body pos="-0.051 0.0575 -0.054" childclass="wheel"><joint name="joint_wheel_l_07"/><geom/></body>
                                            <geom name="car8_geom" pos="0.0 0.0 0.0" type="mesh" mesh="module_asm_0107" material="geom" euler="270 270 0" rgba="0.8 0.7 .6 1"/>
                                            <body pos="-0.051 0.0025 -0.054" childclass="wheel"><joint name="joint_wheel_r_07"/><geom/></body>

                                            <body name="car9" pos="-0.08075 0 0.0" childclass="car">
                                                <joint name="joint08" pos="-0.024 0.033 -0.030"/>
                                                <body pos="-0.051 0.0575 -0.054" childclass="wheel"><joint name="joint_wheel_l_08"/><geom/></body>
                                                <geom name="car9_geom" pos="0.0 0.0 0.0" type="mesh" mesh="module_asm_0107" material="geom" euler="270 270 0" rgba="0.8 0.7 .6 1"/>
                                                <body pos="-0.051 0.0025 -0.054" childclass="wheel"><joint name="joint_wheel_r_08"/><geom/></body>
                                            </body>
                                        </body>
                                    </body>
                                </body>
                            </body>
                        </body>
                    </body>
                </body>
        </body>
    </worldbody>

    <actuator >
        <position name="actuator_joint01" joint="joint01"/>
        <position name="actuator_joint02" joint="joint02"/>
        <position name="actuator_joint03" joint="joint03"/>
        <position name="actuator_joint04" joint="joint04"/>
        <position name="actuator_joint05" joint="joint05"/>
        <position name="actuator_joint06" joint="joint06"/>
        <position name="actuator_joint07" joint="joint07"/>
        <position name="actuator_joint08" joint="joint08"/>
    </actuator>

    <sensor>
        <actuatorfrc name="sensor_actuatorfrc_joint01" actuator="actuator_joint01" />
        <actuatorfrc name="sensor_actuatorfrc_joint02" actuator="actuator_joint02" />
        <actuatorfrc name="sensor_actuatorfrc_joint03" actuator="actuator_joint03" />
        <actuatorfrc name="sensor_actuatorfrc_joint04" actuator="actuator_joint04" />
        <actuatorfrc name="sensor_actuatorfrc_joint05" actuator="actuator_joint05" />
        <actuatorfrc name="sensor_actuatorfrc_joint06" actuator="actuator_joint06" />
        <actuatorfrc name="sensor_actuatorfrc_joint07" actuator="actuator_joint07" />
        <actuatorfrc name="sensor_actuatorfrc_joint08" actuator="actuator_joint08" />

        <velocimeter name="sensor_velocimeter" site="site_head"/>
        <accelerometer name="sensor_accelerometer" site="site_head"/>
    </sensor>
</mujoco>

