<mujoco model="planar_snake_car_servo">
    <compiler angle="degree" coordinate="local" inertiafromgeom="true"/>

    <option integrator="Euler" timestep="0.0125">
        <flag energy="enable" clampctrl="enable"/>
    </option>

    <size nconmax="1000"/>

    <default>
        <geom conaffinity="0" condim="3" friction="1 0.05 0.00001" margin="0.01" density="600" />

        <joint armature='0.001' damping="0" frictionloss="0.001" />

        <default class="wheel">
            <joint axis="0 1 0" type="hinge" damping="0.2"/>
            <geom type="cylinder" fromto="0 0 0  0 0.025 0" size="0.05" material="geom" rgba=".9 .9 .9 1" friction="1.25 1.0 0.0001"/>
        </default>

        <default class="car">
            <!-- <geom type="mesh" mesh="module_asm" fitscale="1"/> -->
            <geom material="geom" rgba="0.8 0.7 .6 1" />
            <joint pos="0 0 0" axis="0 0 1" type="hinge" limited="true" range="-90 90"/>
        </default>


        <position ctrllimited="true" ctrlrange="-1.5 1.5" forcelimited="true" forcerange="-20.0 20.0" kp="20" gear="1"/>

    </default>

    <asset>
        <texture builtin="gradient" height="100" rgb1="1 1 1" rgb2="0 0 0" type="skybox" width="100"/>
        <texture builtin="flat" height="1278" mark="cross" markrgb="1 1 1" name="texgeom" random="0.01"
                 rgb1="0.8 0.6 0.4" rgb2="0.8 0.6 0.4" type="cube" width="127"/>
        <texture builtin="checker" height="100" name="texplane" rgb1="0 0 0" rgb2="0.8 0.8 0.8" type="2d" width="100"/>
        <material name="MatPlane" reflectance="0.5" shininess="1" specular="1" texrepeat="80 80" texture="texplane"/>
        <material name="geom" texture="texgeom" texuniform="true"/>
        <material name="MatTarget" rgba="1 0 0 1" reflectance="0.05" shininess="0.1" specular="0.1"/>
        <mesh file="module_asm.stl" scale="0.005 0.005 0.005"/>
    </asset>


    <visual>
        <map znear="0.0625"  />
        <quality shadowsize="4096"/>

    </visual>


    <worldbody>
        <light cutoff="100" diffuse="1 1 1" dir="-0 0 -1.3" directional="true" exponent="1" pos="0 0 1.3"
               specular=".1 .1 .1"/>
        <geom name="floor" size="80 80 10" material="MatPlane" conaffinity="1" condim="3" pos="0 0 -0.1" rgba="0.8 0.9 0.8 1" type="plane"/>

        <!-- the first object is a target ball -->
        <body name="target_ball" pos="0 0 0.1">
            <joint axis="1 0 0" name="target_slider_x" type="slide"/>
            <joint axis="0 1 0" name="target_slider_y" type="slide"/>
            <geom name="target_ball_geom" type="sphere" pos="0 0 0" size="0.02" material="MatTarget"/>
            <camera name="track_ball" mode="trackcom" pos="0 -4 6" euler="30 0 0"/>
            <camera name="track_ball2" mode="targetbodycom" pos="0 0 1" zaxis="0 0 90" />
        </body>

        <!-- the second object is the robot -->
        <body name="car1" pos="0 0 0.0">
            <site name='site_head' pos='0 0 0.0' type='box'  size='.01 .01 .01'/>
            <geom name="head" pos="0 0 0.1" type="mesh" mesh="module_asm" euler="270 270 0"/>
            <!-- <geom name="head" pos="-0.175 0 0" size="0.125 0.05 0.05" type="box" material="geom" rgba="0.8 0.7 .6 1"/> -->
        </body>



    </worldbody>
</mujoco>
